Workbook

Sheet Players
A1: Player Name | B1: Role | C1: Country | D1: DWL Team | E1: Sold Price | F1: Status
A2: Alana King | B2: allrounder | C2: Australia | D2: Singara Singapengal | E2: 14.5
A3: Annabel Sutherland | B3: allrounder | C3: Australia | D3: Sarafa Strikers | E3: 13.5
A4: Ashleigh Gardner | B4: allrounder | C4: Australia | D4: Gully Divas | E4: 25
A5: Beth Mooney | B5: wicketkeeper | C5: Australia | D5: Sarafa Strikers | E5: 18
A6: Ellyse Perry | B6: allrounder | C6: Australia | D6: Vanitha Warriors | E6: 27.5
A7: Georgia Voll | B7: batter | C7: Australia | D7: Rajputana Ranis | E7: 4
A8: Georgia Wareham | B8: allrounder | C8: Australia | D8: Rajputana Ranis | E8: 4
A9: Grace Harris | B9: allrounder | C9: Australia | D9: Sarafa Strikers | E9: 5
A10: Kim Garth | B10: allrounder | C10: Australia | D10: Konkan Queens | E10: 7.5
A11: Lucy Hamilton | B11: allrounder | C11: Australia | D11: Konkan Queens | E11: 0.5
A12: Megan Schutt | B12: bowler | C12: Australia | D12: Janaki Royals | E12: 14.5
A13: Nicola Carey | B13: bowler | C13: Australia | D13: Vanitha Warriors | E13: 2.5
... A16: Tahlia McGrath | B16: allrounder | C16: Australia | D16: Janaki Royals | E16: 10.5
A17: Dilara Akter | B17: wicketkeeper | C17: Bangladesh
A18: Fahima Khatun | B18: bowler | C18: Bangladesh
A19: Fariha Trisna | B19: bowler | C19: Bangladesh
A20: Juairiya Ferdous | B20: wicketkeeper | C20: Bangladesh
A21: Marufa Akter | B21: bowler | C21: Bangladesh
A22: Nahida Akter | B22: bowler | C22: Bangladesh | D22: Gully Divas | E22: 1
A23: Nigar Sultana | B23: wicketkeeper | C23: Bangladesh | D23: Gully Divas | E23: 1
A24: Rabeya Khan | B24: allrounder | C24: Bangladesh
A25: Ritu Moni | B25: allrounder | C25: Bangladesh
A26: Sharmin Akhter | B26: batter | C26: Bangladesh
A27: Shorna Akter | B27: allrounder | C27: Bangladesh
A28: Sobhana Mostary | B28: batter | C28: Bangladesh
A29: Sultana Khatun | B29: bowler | C29: Bangladesh
A30: Sumaiya Akther | B30: wicketkeeper | C30: Bangladesh
A31: Taj Nehar | B31: batter | C31: Bangladesh
A32: Alice Capsey | B32: allrounder | C32: England | D32: Rajputana Ranis | E32: 16
A33: Amy Jones | B33: wicketkeeper | C33: England | D33: Sarafa Strikers | E33: 9
A34: Charlie Dean | B34: allrounder | C34: England | D34: Gully Divas | E34: 13
A35: Dani Gibson | B35: allrounder | C35: England
A36: Danni Wyatt-Hodge | B36: batter | C36: England | D36: Sarafa Strikers | E36: 9
A37: Freya Kemp | B37: allrounder | C37: England | D37: Sarafa Strikers | E37: 1
A38: Heather Knight | B38: batter | C38: England | D38: Singara Singapengal | E38: 4
A39: Issy Wong | B39: bowler | C39: England | D39: Janaki Royals | E39: 2
A40: Lauren Bell | B40: bowler | C40: England | D40: Konkan Queens | E40: 19
A41: Lauren Filer | B41: bowler | C41: England | D41: Janaki Royals | E41: 1
A42: Linsey Smith | B42: bowler | C42: England | D42: Sarafa Strikers | E42: 3
...

Sheet DWLTeams
A1: Abbrv | B1: Team Name
A2: GD | B2: Gully Divas
A3: JR | B3: Janaki Royals
A4: KQ | B4: Konkan Queens
A5: RR | B5: Rajputana Ranis
A6: SS | B6: Sarafa Strikers
A7: SGS | B7: Singara Singapengal
A8: VW | B8: Vanitha Warriors

Sheet GD
A1: GULLY DIVAS
A5: Team Player No. | B5: Player Name | C5: Country | D5: Captain/ Vice-Captain | E5: Status
A6: 1 | B6: Ashleigh Gardner | C6: =IFERROR(VLOOKUP(GD[[#This Row],[Player Name]],Players!A:D,3,0),"") -> Australia | D6: Captain | E6: =IFERROR(VLOOKUP(GD[[#This Row],[Player Name]],Players!A:F,6,FALSE),"") -> 0
A7: 2 | B7: Charlie Dean | C7: =IFERROR(VLOOKUP(GD[[#This Row],[Player Name]],Players!A:D,3,0),"") -> England | E7: =IFERROR(VLOOKUP(GD[[#This Row],[Player Name]],Players!A:F,6,FALSE),"") -> 0
A8: 3 | B8: Chloe Tryon | C8: =IFERROR(VLOOKUP(GD[[#This Row],[Player Name]],Players!A:D,3,0),"") -> South Africa | E8: =IFERROR(VLOOKUP(GD[[#This Row],[Player Name]],Players!A:F,6,FALSE),"") -> 0
A9: 4 | B9: Deandra Dottin | C9: =IFERROR(VLOOKUP(GD[[#This Row],[Player Name]],Players!A:D,3,0),"") -> West Indies | E9: =IFERROR(VLOOKUP(GD[[#This Row],[Player Name]],Players!A:F,6,FALSE),"") -> 0
A10: 5 | B10: Fatima Sana | C10: =IFERROR(VLOOKUP(GD[[#This Row],[Player Name]],Players!A:D,3,0),"") -> Pakistan | E10: =IFERROR(VLOOKUP(GD[[#This Row],[Player Name]],Players!A:F,6,FALSE),"") -> 0
A11: 6 | B11: Karabo Meso | C11: =IFERROR(VLOOKUP(GD[[#This Row],[Player Name]],Players!A:D,3,0),"") -> South Africa | E11: =IFERROR(VLOOKUP(GD[[#This Row],[Player Name]],Players!A:F,6,FALSE),"") -> 0
A12: 7 | B12: Melie Kerr | C12: =IFERROR(VLOOKUP(GD[[#This Row],[Player Name]],Players!A:D,3,0),"") -> New Zealand | D12: Vice-Captain | E12: =IFERROR(VLOOKUP(GD[[#This Row],[Player Name]],Players!A:F,6,FALSE),"") -> 0
A13: 8 | B13: Nahida Akter | C13: =IFERROR(VLOOKUP(GD[[#This Row],[Player Name]],Players!A:D,3,0),"") -> Bangladesh | E13: =IFERROR(VLOOKUP(GD[[#This Row],[Player Name]],Players!A:F,6,FALSE),"") -> 0
A14: 9 | B14: Nandani Sharma | C14: =IFERROR(VLOOKUP(GD[[#This Row],[Player Name]],Players!A:D,3,0),"") -> India | E14: =IFERROR(VLOOKUP(GD[[#This Row],[Player Name]],Players!A:F,6,FALSE),"") -> 0
A15: 10 | B15: Nigar Sultana | C15: =IFERROR(VLOOKUP(GD[[#This Row],[Player Name]],Players!A:D,3,0),"") -> Bangladesh | E15: =IFERROR(VLOOKUP(GD[[#This Row],[Player Name]],Players!A:F,6,FALSE),"") -> 0
A16: 11 | B16: Pippa Sproul | C16: =IFERROR(VLOOKUP(GD[[#This Row],[Player Name]],Players!A:D,3,0),"") -> Scotland | E16: =IFERROR(VLOOKUP(GD[[#This Row],[Player Name]],Players!A:F,6,FALSE),"") -> 0
A17: 12 | B17: Prema Rawat | C17: =IFERROR(VLOOKUP(GD[[#This Row],[Player Name]],Players!A:D,3,0),"") -> India | E17: =IFERROR(VLOOKUP(GD[[#This Row],[Player Name]],Players!A:F,6,FALSE),"") -> Replacement
A18: 13 | B18: Sarah Bryce | C18: =IFERROR(VLOOKUP(GD[[#This Row],[Player Name]],Players!A:D,3,0),"") -> Scotland | E18: =IFERROR(VLOOKUP(GD[[#This Row],[Player Name]],Players!A:F,6,FALSE),"") -> 0
A19: 14 | B19: Shree Charani | C19: =IFERROR(VLOOKUP(GD[[#This Row],[Player Name]],Players!A:D,3,0),"") -> India | E19: =IFERROR(VLOOKUP(GD[[#This Row],[Player Name]],Players!A:F,6,FALSE),"") -> 0
A20: 15 | B20: Shreyanka Patil | C20: =IFERROR(VLOOKUP(GD[[#This Row],[Player Name]],Players!A:D,3,0),"") -> India | E20: =IFERROR(VLOOKUP(GD[[#This Row],[Player Name]],Players!A:F,6,FALSE),"") -> Injured
A21: 16 | B21: Sophia Dunkley | C21: =IFERROR(VLOOKUP(GD[[#This Row],[Player Name]],Players!A:D,3,0),"") -> England | E21: =IFERROR(VLOOKUP(GD[[#This Row],[Player Name]],Players!A:F,6,FALSE),"") -> 0
A22: 17 | B22: Sterre Kalis | C22: =IFERROR(VLOOKUP(GD[[#This Row],[Player Name]],Players!A:D,3,0),"") -> Netherlands | E22: =IFERROR(VLOOKUP(GD[[#This Row],[Player Name]],Players!A:F,6,FALSE),"") -> 0
A23: 18 | B23: Tilly Corteen-Coleman | C23: =IFERROR(VLOOKUP(GD[[#This Row],[Player Name]],Players!A:D,3,0),"") -> England | E23: =IFERROR(VLOOKUP(GD[[#This Row],[Player Name]],Players!A:F,6,FALSE),"") -> 0

Sheet JR
A1: JANAKI ROYALS
A5: Team Player No. | B5: Player Name | C5: Country | D5: Captain/ Vice-Captain | E5: Status
A6: 1 | B6: Aaliyah Alleyne | C6: =IFERROR(VLOOKUP(JR[[#This Row],[Player Name]],Players!A:D,3,0),"") -> West Indies | E6: =IFERROR(VLOOKUP(JR[[#This Row],[Player Name]],Players!A:F,6,FALSE),"") -> 0
A7: 2 | B7: Hayley Matthews | C7: =IFERROR(VLOOKUP(JR[[#This Row],[Player Name]],Players!A:D,3,0),"") -> West Indies | D7: Captain | E7: =IFERROR(VLOOKUP(JR[[#This Row],[Player Name]],Players!A:F,6,FALSE),"") -> 0
A8: 3 | B8: Issy Wong | C8: =IFERROR(VLOOKUP(JR[[#This Row],[Player Name]],Players!A:D,3,0),"") -> England | E8: =IFERROR(VLOOKUP(JR[[#This Row],[Player Name]],Players!A:F,6,FALSE),"") -> 0
A9: 4 | B9: Izzy Sharp | C9: =IFERROR(VLOOKUP(JR[[#This Row],[Player Name]],Players!A:D,3,0),"") -> New Zealand | E9: =IFERROR(VLOOKUP(JR[[#This Row],[Player Name]],Players!A:F,6,FALSE),"") -> 0
A10: 5 | B10: Kathryn Bryce | C10: =IFERROR(VLOOKUP(JR[[#This Row],[Player Name]],Players!A:D,3,0),"") -> Scotland | E10: =IFERROR(VLOOKUP(JR[[#This Row],[Player Name]],Players!A:F,6,FALSE),"") -> 0
A11: 6 | B11: Lauren Filer | C11: =IFERROR(VLOOKUP(JR[[#This Row],[Player Name]],Players!A:D,3,0),"") -> England | E11: =IFERROR(VLOOKUP(JR[[#This Row],[Player Name]],Players!A:F,6,FALSE),"") -> 0
A12: 7 | B12: Lea Tahuhu | C12: =IFERROR(VLOOKUP(JR[[#This Row],[Player Name]],Players!A:D,3,0),"") -> New Zealand | E12: =IFERROR(VLOOKUP(JR[[#This Row],[Player Name]],Players!A:F,6,FALSE),"") -> 0
A13: 8 | B13: Megan Schutt | C13: =IFERROR(VLOOKUP(JR[[#This Row],[Player Name]],Players!A:D,3,0),"") -> Australia | E13: =IFERROR(VLOOKUP(JR[[#This Row],[Player Name]],Players!A:F,6,FALSE),"") -> 0
A14: 9 | B14: Muneeba Ali | C14: =IFERROR(VLOOKUP(JR[[#This Row],[Player Name]],Players!A:D,3,0),"") -> Pakistan | E14: =IFERROR(VLOOKUP(JR[[#This Row],[Player Name]],Players!A:F,6,FALSE),"") -> 0
A15: 10 | B15: Nat Sciver-Brunt | C15: =IFERROR(VLOOKUP(JR[[#This Row],[Player Name]],Players!A:D,3,0),"") -> England | D15: Vice-Captain | E15: =IFERROR(VLOOKUP(JR[[#This Row],[Player Name]],Players!A:F,6,FALSE),"") -> 0
A16: 11 | B16: Robine Rijke | C16: =IFERROR(VLOOKUP(JR[[#This Row],[Player Name]],Players!A:D,3,0),"") -> Netherlands | E16: =IFERROR(VLOOKUP(JR[[#This Row],[Player Name]],Players!A:F,6,FALSE),"") -> 0
A17: 12 | B17: Sugandika Kumari | C17: =IFERROR(VLOOKUP(JR[[#This Row],[Player Name]],Players!A:D,3,0),"") -> Sri Lanka | E17: =IFERROR(VLOOKUP(JR[[#This Row],[Player Name]],Players!A:F,6,FALSE),"") -> 0
A18: 13 | B18: Tahlia McGrath | C18: =IFERROR(VLOOKUP(JR[[#This Row],[Player Name]],Players!A:D,3,0),"") -> Australia | E18: =IFERROR(VLOOKUP(JR[[#This Row],[Player Name]],Players!A:F,6,FALSE),"") -> 0
A19: 14 | B19: Tazmin Brits | C19: =IFERROR(VLOOKUP(JR[[#This Row],[Player Name]],Players!A:D,3,0),"") -> South Africa | E19: =IFERROR(VLOOKUP(JR[[#This Row],[Player Name]],Players!A:F,6,FALSE),"") -> 0
A20: 15 | B20: Vishmi Gunaratne | C20: =IFERROR(VLOOKUP(JR[[#This Row],[Player Name]],Players!A:D,3,0),"") -> Sri Lanka | E20: =IFERROR(VLOOKUP(JR[[#This Row],[Player Name]],Players!A:F,6,FALSE),"") -> 0
A21: 16 | B21: Zaida James | C21: =IFERROR(VLOOKUP(JR[[#This Row],[Player Name]],Players!A:D,3,0),"") -> West Indies | E21: =IFERROR(VLOOKUP(JR[[#This Row],[Player Name]],Players!A:F,6,FALSE),"") -> 0
A22: 17 | C22: =IFERROR(VLOOKUP(JR[[#This Row],[Player Name]],Players!A:D,3,0),"") | E22: =IFERROR(VLOOKUP(JR[[#This Row],[Player Name]],Players!A:F,6,FALSE),"")
A23: 18 | C23: =IFERROR(VLOOKUP(JR[[#This Row],[Player Name]],Players!A:D,3,0),"") | E23: =IFERROR(VLOOKUP(JR[[#This Row],[Player Name]],Players!A:F,6,FALSE),"")

Sheet KQ
A1: KONKAN QUEENS
A5: Team Player No. | B5: Player Name | C5: Country | D5: Captain/ Vice-Captain | E5: Status
A6: 1 | B6: Chinelle Henry | C6: =IFERROR(VLOOKUP(KQ[[#This Row],[Player Name]],Players!A:D,3,0),"") -> West Indies | E6: =IFERROR(VLOOKUP(KQ[[#This Row],[Player Name]],Players!A:F,6,FALSE),"") -> 0
A7: 2 | B7: Dane van Niekerk | C7: =IFERROR(VLOOKUP(KQ[[#This Row],[Player Name]],Players!A:D,3,0),"") -> South Africa | E7: =IFERROR(VLOOKUP(KQ[[#This Row],[Player Name]],Players!A:F,6,FALSE),"") -> 0
A8: 3 | B8: Deepti Sharma | C8: =IFERROR(VLOOKUP(KQ[[#This Row],[Player Name]],Players!A:D,3,0),"") -> India | D8: Captain | E8: =IFERROR(VLOOKUP(KQ[[#This Row],[Player Name]],Players!A:F,6,FALSE),"") -> 0
A9: 4 | B9: Gaby Lewis | C9: =IFERROR(VLOOKUP(KQ[[#This Row],[Player Name]],Players!A:D,3,0),"") -> Ireland | E9: =IFERROR(VLOOKUP(KQ[[#This Row],[Player Name]],Players!A:F,6,FALSE),"") -> 0
A10: 5 | B10: Kim Garth | C10: =IFERROR(VLOOKUP(KQ[[#This Row],[Player Name]],Players!A:D,3,0),"") -> Australia | E10: =IFERROR(VLOOKUP(KQ[[#This Row],[Player Name]],Players!A:F,6,FALSE),"") -> 0
A11: 6 | B11: Lauren Bell | C11: =IFERROR(VLOOKUP(KQ[[#This Row],[Player Name]],Players!A:D,3,0),"") -> England | E11: =IFERROR(VLOOKUP(KQ[[#This Row],[Player Name]],Players!A:F,6,FALSE),"") -> 0
A12: 7 | B12: Lucy Hamilton | C12: =IFERROR(VLOOKUP(KQ[[#This Row],[Player Name]],Players!A:D,3,0),"") -> Australia | E12: =IFERROR(VLOOKUP(KQ[[#This Row],[Player Name]],Players!A:F,6,FALSE),"") -> 0
A13: 8 | B13: Phoebe Litchfield | C13: =IFERROR(VLOOKUP(KQ[[#This Row],[Player Name]],Players!A:D,3,0),"") -> Australia | E13: =IFERROR(VLOOKUP(KQ[[#This Row],[Player Name]],Players!A:F,6,FALSE),"") -> 0
A14: 9 | B14: Polly Inglis | C14: =IFERROR(VLOOKUP(KQ[[#This Row],[Player Name]],Players!A:D,3,0),"") -> New Zealand | E14: =IFERROR(VLOOKUP(KQ[[#This Row],[Player Name]],Players!A:F,6,FALSE),"") -> 0
A15: 10 | B15: Sinalo Jafta | C15: =IFERROR(VLOOKUP(KQ[[#This Row],[Player Name]],Players!A:D,3,0),"") -> South Africa | E15: =IFERROR(VLOOKUP(KQ[[#This Row],[Player Name]],Players!A:F,6,FALSE),"") -> 0
A16: 11 | B16: Smriti Mandhana | C16: =IFERROR(VLOOKUP(KQ[[#This Row],[Player Name]],Players!A:D,3,0),"") -> India | E16: =IFERROR(VLOOKUP(KQ[[#This Row],[Player Name]],Players!A:F,6,FALSE),"") -> 0
A17: 12 | B17: Sophie Ecclestone | C17: =IFERROR(VLOOKUP(KQ[[#This Row],[Player Name]],Players!A:D,3,0),"") -> England | D17: Vice-Captain | E17: =IFERROR(VLOOKUP(KQ[[#This Row],[Player Name]],Players!A:F,6,FALSE),"") -> 0
A18: 13 | B18: Sophie Molineux | C18: =IFERROR(VLOOKUP(KQ[[#This Row],[Player Name]],Players!A:D,3,0),"") -> Australia | E18: =IFERROR(VLOOKUP(KQ[[#This Row],[Player Name]],Players!A:F,6,FALSE),"") -> 0
A19: 14 | C19: =IFERROR(VLOOKUP(KQ[[#This Row],[Player Name]],Players!A:D,3,0),"") | E19: =IFERROR(VLOOKUP(KQ[[#This Row],[Player Name]],Players!A:F,6,FALSE),"")
A20: 15 | C20: =IFERROR(VLOOKUP(KQ[[#This Row],[Player Name]],Players!A:D,3,0),"") | E20: =IFERROR(VLOOKUP(KQ[[#This Row],[Player Name]],Players!A:F,6,FALSE),"")
A21: 16 | C21: =IFERROR(VLOOKUP(KQ[[#This Row],[Player Name]],Players!A:D,3,0),"") | E21: =IFERROR(VLOOKUP(KQ[[#This Row],[Player Name]],Players!A:F,6,FALSE),"")
A22: 17 | C22: =IFERROR(VLOOKUP(KQ[[#This Row],[Player Name]],Players!A:D,3,0),"") | E22: =IFERROR(VLOOKUP(KQ[[#This Row],[Player Name]],Players!A:F,6,FALSE),"")
A23: 18 | C23: =IFERROR(VLOOKUP(KQ[[#This Row],[Player Name]],Players!A:D,3,0),"") | E23: =IFERROR(VLOOKUP(KQ[[#This Row],[Player Name]],Players!A:F,6,FALSE),"")

Sheet RR
A1: RAJPUTANA RANIS
A5: Team Player No. | B5: Player Name | C5: Country | D5: Captain/ Vice-Captain | E5: Status
A6: 1 | B6: Alice Capsey | C6: =IFERROR(VLOOKUP(RR[[#This Row],[Player Name]],Players!A:D,3,0),"") -> England | E6: =IFERROR(VLOOKUP(RR[[#This Row],[Player Name]],Players!A:F,6,FALSE),"") -> 0
A7: 2 | B7: Arundhati Reddy | C7: =IFERROR(VLOOKUP(RR[[#This Row],[Player Name]],Players!A:D,3,0),"") -> India | E7: =IFERROR(VLOOKUP(RR[[#This Row],[Player Name]],Players!A:F,6,FALSE),"") -> 0
A8: 3 | B8: Ayabonga Khaka | C8: =IFERROR(VLOOKUP(RR[[#This Row],[Player Name]],Players!A:D,3,0),"") -> South Africa | E8: =IFERROR(VLOOKUP(RR[[#This Row],[Player Name]],Players!A:F,6,FALSE),"") -> 0
A9: 4 | B9: Chamari Athapaththu | C9: =IFERROR(VLOOKUP(RR[[#This Row],[Player Name]],Players!A:D,3,0),"") -> Sri Lanka | D9: Vice-Captain | E9: =IFERROR(VLOOKUP(RR[[#This Row],[Player Name]],Players!A:F,6,FALSE),"") -> 0
A10: 5 | B10: Georgia Voll | C10: =IFERROR(VLOOKUP(RR[[#This Row],[Player Name]],Players!A:D,3,0),"") -> Australia | E10: =IFERROR(VLOOKUP(RR[[#This Row],[Player Name]],Players!A:F,6,FALSE),"") -> 0
A11: 6 | B11: Georgia Wareham | C11: =IFERROR(VLOOKUP(RR[[#This Row],[Player Name]],Players!A:D,3,0),"") -> Australia | E11: =IFERROR(VLOOKUP(RR[[#This Row],[Player Name]],Players!A:F,6,FALSE),"") -> 0
A12: 7 | B12: Jemimah Rodrigues | C12: =IFERROR(VLOOKUP(RR[[#This Row],[Player Name]],Players!A:D,3,0),"") -> India | E12: =IFERROR(VLOOKUP(RR[[#This Row],[Player Name]],Players!A:F,6,FALSE),"") -> 0
A13: 8 | B13: Jess Kerr | C13: =IFERROR(VLOOKUP(RR[[#This Row],[Player Name]],Players!A:D,3,0),"") -> New Zealand | E13: =IFERROR(VLOOKUP(RR[[#This Row],[Player Name]],Players!A:F,6,FALSE),"") -> 0
A14: 9 | B14: Kranti Gaud | C14: =IFERROR(VLOOKUP(RR[[#This Row],[Player Name]],Players!A:D,3,0),"") -> India | E14: =IFERROR(VLOOKUP(RR[[#This Row],[Player Name]],Players!A:F,6,FALSE),"") -> 0
A15: 10 | B15: Nashra Sandhu | C15: =IFERROR(VLOOKUP(RR[[#This Row],[Player Name]],Players!A:D,3,0),"") -> Pakistan | E15: =IFERROR(VLOOKUP(RR[[#This Row],[Player Name]],Players!A:F,6,FALSE),"") -> 0
A16: 11 | B16: Shabnim Ismail | C16: =IFERROR(VLOOKUP(RR[[#This Row],[Player Name]],Players!A:D,3,0),"") -> South Africa | E16: =IFERROR(VLOOKUP(RR[[#This Row],[Player Name]],Players!A:F,6,FALSE),"") -> 0
A17: 12 | B17: Sophie Devine | C17: =IFERROR(VLOOKUP(RR[[#This Row],[Player Name]],Players!A:D,3,0),"") -> New Zealand | D17: Captain | E17: =IFERROR(VLOOKUP(RR[[#This Row],[Player Name]],Players!A:F,6,FALSE),"") -> 0
A18: 13 | B18: Sune Luus | C18: =IFERROR(VLOOKUP(RR[[#This Row],[Player Name]],Players!A:D,3,0),"") -> South Africa | E18: =IFERROR(VLOOKUP(RR[[#This Row],[Player Name]],Players!A:F,6,FALSE),"") -> 0
A19: 14 | B19: Yastika Bhatia | C19: =IFERROR(VLOOKUP(RR[[#This Row],[Player Name]],Players!A:D,3,0),"") -> India | E19: =IFERROR(VLOOKUP(RR[[#This Row],[Player Name]],Players!A:F,6,FALSE),"") -> 0
A20: 15 | C20: =IFERROR(VLOOKUP(RR[[#This Row],[Player Name]],Players!A:D,3,0),"") | E20: =IFERROR(VLOOKUP(RR[[#This Row],[Player Name]],Players!A:F,6,FALSE),"")
A21: 16 | C21: =IFERROR(VLOOKUP(RR[[#This Row],[Player Name]],Players!A:D,3,0),"") | E21: =IFERROR(VLOOKUP(RR[[#This Row],[Player Name]],Players!A:F,6,FALSE),"")
A22: 17 | C22: =IFERROR(VLOOKUP(RR[[#This Row],[Player Name]],Players!A:D,3,0),"") | E22: =IFERROR(VLOOKUP(RR[[#This Row],[Player Name]],Players!A:F,6,FALSE),"")
A23: 18 | C23: =IFERROR(VLOOKUP(RR[[#This Row],[Player Name]],Players!A:D,3,0),"") | E23: =IFERROR(VLOOKUP(RR[[#This Row],[Player Name]],Players!A:F,6,FALSE),"")

Sheet SS
A1: SARAFA STRIKERS
A5: Team Player No. | B5: Player Name | C5: Country | D5: Captain/ Vice-Captain | E5: Status
A6: 1 | B6: Amy Jones | C6: =IFERROR(VLOOKUP(SS[[#This Row],[Player Name]],Players!A:D,3,0),"") -> England | E6: =IFERROR(VLOOKUP(SS[[#This Row],[Player Name]],Players!A:F,6,FALSE),"") -> 0
A7: 2 | B7: Annabel Sutherland | C7: =IFERROR(VLOOKUP(SS[[#This Row],[Player Name]],Players!A:D,3,0),"") -> Australia | E7: =IFERROR(VLOOKUP(SS[[#This Row],[Player Name]],Players!A:F,6,FALSE),"") -> 0
A8: 3 | B8: Beth Mooney | C8: =IFERROR(VLOOKUP(SS[[#This Row],[Player Name]],Players!A:D,3,0),"") -> Australia | E8: =IFERROR(VLOOKUP(SS[[#This Row],[Player Name]],Players!A:F,6,FALSE),"") -> 0
A9: 4 | B9: Bree Illing | C9: =IFERROR(VLOOKUP(SS[[#This Row],[Player Name]],Players!A:D,3,0),"") -> New Zealand | E9: =IFERROR(VLOOKUP(SS[[#This Row],[Player Name]],Players!A:F,6,FALSE),"") -> 0
A10: 5 | B10: Danni Wyatt-Hodge | C10: =IFERROR(VLOOKUP(SS[[#This Row],[Player Name]],Players!A:D,3,0),"") -> England | E10: =IFERROR(VLOOKUP(SS[[#This Row],[Player Name]],Players!A:F,6,FALSE),"") -> 0
A11: 6 | B11: Freya Kemp | C11: =IFERROR(VLOOKUP(SS[[#This Row],[Player Name]],Players!A:D,3,0),"") -> England | E11: =IFERROR(VLOOKUP(SS[[#This Row],[Player Name]],Players!A:F,6,FALSE),"") -> 0
A12: 7 | B12: Grace Harris | C12: =IFERROR(VLOOKUP(SS[[#This Row],[Player Name]],Players!A:D,3,0),"") -> Australia | E12: =IFERROR(VLOOKUP(SS[[#This Row],[Player Name]],Players!A:F,6,FALSE),"") -> 0
A13: 8 | B13: Karishma Ramharack | C13: =IFERROR(VLOOKUP(SS[[#This Row],[Player Name]],Players!A:D,3,0),"") -> West Indies | E13: =IFERROR(VLOOKUP(SS[[#This Row],[Player Name]],Players!A:F,6,FALSE),"") -> 0
A14: 9 | B14: Laura Wolvaardt | C14: =IFERROR(VLOOKUP(SS[[#This Row],[Player Name]],Players!A:D,3,0),"") -> South Africa | D14: Captain | E14: =IFERROR(VLOOKUP(SS[[#This Row],[Player Name]],Players!A:F,6,FALSE),"") -> 0
A15: 10 | B15: Linsey Smith | C15: =IFERROR(VLOOKUP(SS[[#This Row],[Player Name]],Players!A:D,3,0),"") -> England | E15: =IFERROR(VLOOKUP(SS[[#This Row],[Player Name]],Players!A:F,6,FALSE),"") -> 0
A16: 11 | B16: Nonkululeko Mlaba | C16: =IFERROR(VLOOKUP(SS[[#This Row],[Player Name]],Players!A:D,3,0),"") -> South Africa | D16: Vice-Captain | E16: =IFERROR(VLOOKUP(SS[[#This Row],[Player Name]],Players!A:F,6,FALSE),"") -> 0
A17: 12 | B17: Orla Prendergast | C17: =IFERROR(VLOOKUP(SS[[#This Row],[Player Name]],Players!A:D,3,0),"") -> Ireland | E17: =IFERROR(VLOOKUP(SS[[#This Row],[Player Name]],Players!A:F,6,FALSE),"") -> 0
A18: 13 | B18: Renuka Singh | C18: =IFERROR(VLOOKUP(SS[[#This Row],[Player Name]],Players!A:D,3,0),"") -> India | E18: =IFERROR(VLOOKUP(SS[[#This Row],[Player Name]],Players!A:F,6,FALSE),"") -> 0
A19: 14 | B19: Rosemary Mair | C19: =IFERROR(VLOOKUP(SS[[#This Row],[Player Name]],Players!A:D,3,0),"") -> New Zealand | E19: =IFERROR(VLOOKUP(SS[[#This Row],[Player Name]],Players!A:F,6,FALSE),"") -> 0
A20: 15 | B20: Stafanie Taylor | C20: =IFERROR(VLOOKUP(SS[[#This Row],[Player Name]],Players!A:D,3,0),"") -> West Indies | E20: =IFERROR(VLOOKUP(SS[[#This Row],[Player Name]],Players!A:F,6,FALSE),"") -> 0
A21: 16 | C21: =IFERROR(VLOOKUP(SS[[#This Row],[Player Name]],Players!A:D,3,0),"") | E21: =IFERROR(VLOOKUP(SS[[#This Row],[Player Name]],Players!A:F,6,FALSE),"")
A22: 17 | C22: =IFERROR(VLOOKUP(SS[[#This Row],[Player Name]],Players!A:D,3,0),"") | E22: =IFERROR(VLOOKUP(SS[[#This Row],[Player Name]],Players!A:F,6,FALSE),"")
A23: 18 | C23: =IFERROR(VLOOKUP(SS[[#This Row],[Player Name]],Players!A:D,3,0),"") | E23: =IFERROR(VLOOKUP(SS[[#This Row],[Player Name]],Players!A:F,6,FALSE),"")

Sheet SGS
A1: SINGARA SINGAPENGAL
A5: Team Player No. | B5: Player Name | C5: Country | D5: Captain/ Vice-Captain | E5: Status
A6: 1 | B6: Abtaha Maqsood | C6: =IFERROR(VLOOKUP(SGS[[#This Row],[Player Name]],Players!A:D,3,0),"") -> Scotland | E6: =IFERROR(VLOOKUP(SGS[[#This Row],[Player Name]],Players!A:F,6,FALSE),"") -> Injured
A7: 2 | B7: Alana King | C7: =IFERROR(VLOOKUP(SGS[[#This Row],[Player Name]],Players!A:D,3,0),"") -> Australia | E7: =IFERROR(VLOOKUP(SGS[[#This Row],[Player Name]],Players!A:F,6,FALSE),"") -> 0
A8: 3 | B8: Bharti Fulmali | C8: =IFERROR(VLOOKUP(SGS[[#This Row],[Player Name]],Players!A:D,3,0),"") -> India | E8: =IFERROR(VLOOKUP(SGS[[#This Row],[Player Name]],Players!A:F,6,FALSE),"") -> 0
A9: 4 | B9: Brooke Halliday | C9: =IFERROR(VLOOKUP(SGS[[#This Row],[Player Name]],Players!A:D,3,0),"") -> New Zealand | E9: =IFERROR(VLOOKUP(SGS[[#This Row],[Player Name]],Players!A:F,6,FALSE),"") -> 0
A10: 5 | B10: Cara Murray | C10: =IFERROR(VLOOKUP(SGS[[#This Row],[Player Name]],Players!A:D,3,0),"") -> Ireland | E10: =IFERROR(VLOOKUP(SGS[[#This Row],[Player Name]],Players!A:F,6,FALSE),"") -> 0
A11: 6 | B11: Hannah Rainey | C11: =IFERROR(VLOOKUP(SGS[[#This Row],[Player Name]],Players!A:D,3,0),"") -> Scotland | E11: =IFERROR(VLOOKUP(SGS[[#This Row],[Player Name]],Players!A:F,6,FALSE),"") -> Replacement
A12: 7 | B12: Harshitha Samarawickrama | C12: =IFERROR(VLOOKUP(SGS[[#This Row],[Player Name]],Players!A:D,3,0),"") -> Sri Lanka | E12: =IFERROR(VLOOKUP(SGS[[#This Row],[Player Name]],Players!A:F,6,FALSE),"") -> 0
A13: 8 | B13: Heather Knight | C13: =IFERROR(VLOOKUP(SGS[[#This Row],[Player Name]],Players!A:D,3,0),"") -> England | E13: =IFERROR(VLOOKUP(SGS[[#This Row],[Player Name]],Players!A:F,6,FALSE),"") -> 0
A14: 9 | B14: Leah Paul | C14: =IFERROR(VLOOKUP(SGS[[#This Row],[Player Name]],Players!A:D,3,0),"") -> Ireland | E14: =IFERROR(VLOOKUP(SGS[[#This Row],[Player Name]],Players!A:F,6,FALSE),"") -> 0
A15: 10 | B15: Marizanne Kapp | C15: =IFERROR(VLOOKUP(SGS[[#This Row],[Player Name]],Players!A:D,3,0),"") -> South Africa | D15: Captain | E15: =IFERROR(VLOOKUP(SGS[[#This Row],[Player Name]],Players!A:F,6,FALSE),"") -> 0
A16: 11 | B16: Richa Ghosh | C16: =IFERROR(VLOOKUP(SGS[[#This Row],[Player Name]],Players!A:D,3,0),"") -> India | E16: =IFERROR(VLOOKUP(SGS[[#This Row],[Player Name]],Players!A:F,6,FALSE),"") -> 0
A17: 12 | B17: Shafali Verma | C17: =IFERROR(VLOOKUP(SGS[[#This Row],[Player Name]],Players!A:D,3,0),"") -> India | D17: Vice-Captain | E17: =IFERROR(VLOOKUP(SGS[[#This Row],[Player Name]],Players!A:F,6,FALSE),"") -> 0
A18: 13 | B18: Shemaine Campbelle | C18: =IFERROR(VLOOKUP(SGS[[#This Row],[Player Name]],Players!A:D,3,0),"") -> West Indies | E18: =IFERROR(VLOOKUP(SGS[[#This Row],[Player Name]],Players!A:F,6,FALSE),"") -> 0
A19: 14 | C19: =IFERROR(VLOOKUP(SGS[[#This Row],[Player Name]],Players!A:D,3,0),"") | E19: =IFERROR(VLOOKUP(SGS[[#This Row],[Player Name]],Players!A:F,6,FALSE),"")
A20: 15 | C20: =IFERROR(VLOOKUP(SGS[[#This Row],[Player Name]],Players!A:D,3,0),"") | E20: =IFERROR(VLOOKUP(SGS[[#This Row],[Player Name]],Players!A:F,6,FALSE),"")
A21: 16 | C21: =IFERROR(VLOOKUP(SGS[[#This Row],[Player Name]],Players!A:D,3,0),"") | E21: =IFERROR(VLOOKUP(SGS[[#This Row],[Player Name]],Players!A:F,6,FALSE),"")
A22: 17 | C22: =IFERROR(VLOOKUP(SGS[[#This Row],[Player Name]],Players!A:D,3,0),"") | E22: =IFERROR(VLOOKUP(SGS[[#This Row],[Player Name]],Players!A:F,6,FALSE),"")
A23: 18 | C23: =IFERROR(VLOOKUP(SGS[[#This Row],[Player Name]],Players!A:D,3,0),"") | E23: =IFERROR(VLOOKUP(SGS[[#This Row],[Player Name]],Players!A:F,6,FALSE),"")

Sheet VW
A1: VANITHA WARRIORS
A5: Team Player No. | B5: Player Name | C5: Country | D5: Captain/ Vice-Captain | E5: Status
A6: 1 | B6: Afy Fletcher | C6: =IFERROR(VLOOKUP(KT[[#This Row],[Player Name]],Players!A:D,3,0),"") -> West Indies | E6: =IFERROR(VLOOKUP(KT[[#This Row],[Player Name]],Players!A:F,6,FALSE),"") -> 0
A7: 2 | B7: Amy Hunter | C7: =IFERROR(VLOOKUP(KT[[#This Row],[Player Name]],Players!A:D,3,0),"") -> Ireland | E7: =IFERROR(VLOOKUP(KT[[#This Row],[Player Name]],Players!A:F,6,FALSE),"") -> 0
A8: 3 | B8: Annerie Dercksen | C8: =IFERROR(VLOOKUP(KT[[#This Row],[Player Name]],Players!A:D,3,0),"") -> South Africa | E8: =IFERROR(VLOOKUP(KT[[#This Row],[Player Name]],Players!A:F,6,FALSE),"") -> 0
A9: 4 | B9: Ayesha Zafar | C9: =IFERROR(VLOOKUP(KT[[#This Row],[Player Name]],Players!A:D,3,0),"") -> Pakistan | E9: =IFERROR(VLOOKUP(KT[[#This Row],[Player Name]],Players!A:F,6,FALSE),"") -> 0
A10: 5 | B10: Ellyse Perry | C10: =IFERROR(VLOOKUP(KT[[#This Row],[Player Name]],Players!A:D,3,0),"") -> Australia | D10: Captain | E10: =IFERROR(VLOOKUP(KT[[#This Row],[Player Name]],Players!A:F,6,FALSE),"") -> 0
A11: 6 | B11: Georgia Plimmer | C11: =IFERROR(VLOOKUP(KT[[#This Row],[Player Name]],Players!A:D,3,0),"") -> New Zealand | E11: =IFERROR(VLOOKUP(KT[[#This Row],[Player Name]],Players!A:F,6,FALSE),"") -> 0
A12: 7 | B12: Harmanpreet Kaur | C12: =IFERROR(VLOOKUP(KT[[#This Row],[Player Name]],Players!A:D,3,0),"") -> India | D12: Vice-Captain | E12: =IFERROR(VLOOKUP(KT[[#This Row],[Player Name]],Players!A:F,6,FALSE),"") -> 0
A13: 8 | B13: Kayla Reyneke | C13: =IFERROR(VLOOKUP(KT[[#This Row],[Player Name]],Players!A:D,3,0),"") -> South Africa | E13: =IFERROR(VLOOKUP(KT[[#This Row],[Player Name]],Players!A:F,6,FALSE),"") -> 0
A14: 9 | B14: Nadine de Klerk | C14: =IFERROR(VLOOKUP(KT[[#This Row],[Player Name]],Players!A:D,3,0),"") -> South Africa | E14: =IFERROR(VLOOKUP(KT[[#This Row],[Player Name]],Players!A:F,6,FALSE),"") -> 0
A15: 10 | B15: Nicola Carey | C15: =IFERROR(VLOOKUP(KT[[#This Row],[Player Name]],Players!A:D,3,0),"") -> Australia | E15: =IFERROR(VLOOKUP(KT[[#This Row],[Player Name]],Players!A:F,6,FALSE),"") -> 0
A16: 11 | B16: Radha Yadav | C16: =IFERROR(VLOOKUP(KT[[#This Row],[Player Name]],Players!A:D,3,0),"") -> India | E16: =IFERROR(VLOOKUP(KT[[#This Row],[Player Name]],Players!A:F,6,FALSE),"") -> 0
A17: 12 | B17: Sadia Iqbal | C17: =IFERROR(VLOOKUP(KT[[#This Row],[Player Name]],Players!A:D,3,0),"") -> Pakistan | E17: =IFERROR(VLOOKUP(KT[[#This Row],[Player Name]],Players!A:F,6,FALSE),"") -> 0
A18: 13 | B18: Suzie Bates | C18: =IFERROR(VLOOKUP(KT[[#This Row],[Player Name]],Players!A:D,3,0),"") -> New Zealand | E18: =IFERROR(VLOOKUP(KT[[#This Row],[Player Name]],Players!A:F,6,FALSE),"") -> 0
A19: 14 | C19: =IFERROR(VLOOKUP(KT[[#This Row],[Player Name]],Players!A:D,3,0),"") | E19: =IFERROR(VLOOKUP(KT[[#This Row],[Player Name]],Players!A:F,6,FALSE),"")
A20: 15 | C20: =IFERROR(VLOOKUP(KT[[#This Row],[Player Name]],Players!A:D,3,0),"") | E20: =IFERROR(VLOOKUP(KT[[#This Row],[Player Name]],Players!A:F,6,FALSE),"")
A21: 16 | C21: =IFERROR(VLOOKUP(KT[[#This Row],[Player Name]],Players!A:D,3,0),"") | E21: =IFERROR(VLOOKUP(KT[[#This Row],[Player Name]],Players!A:F,6,FALSE),"")
A22: 17 | C22: =IFERROR(VLOOKUP(KT[[#This Row],[Player Name]],Players!A:D,3,0),"") | E22: =IFERROR(VLOOKUP(KT[[#This Row],[Player Name]],Players!A:F,6,FALSE),"")
A23: 18 | C23: =IFERROR(VLOOKUP(KT[[#This Row],[Player Name]],Players!A:D,3,0),"") | E23: =IFERROR(VLOOKUP(KT[[#This Row],[Player Name]],Players!A:F,6,FALSE),"")
